I'm sorry, but an uncaught exception occurred.

While running game code:
  File "game/game_logic_test.rpy", line 50, in script
  File "game/game_logic_test.rpy", line 53, in python
NameError: global name 'false' is not defined

-- Full Traceback ------------------------------------------------------------

Full traceback:
  File "/Users/ZERO/Computing/Ren'Py/renpy/execution.py", line 288, in run
    node.execute()
  File "/Users/ZERO/Computing/Ren'Py/renpy/ast.py", line 718, in execute
    renpy.python.py_exec_bytecode(self.code.bytecode, self.hide, store=self.store)
  File "/Users/ZERO/Computing/Ren'Py/renpy/python.py", line 1297, in py_exec_bytecode
    exec bytecode in globals, locals
  File "game/game_logic_test.rpy", line 53, in <module>
    if ai.check_win(choice[0], choice[1]):
  File "intelligent_agent.py", line 275, in check_win
  File "game_logic.py", line 83, in check_win
NameError: global name 'false' is not defined

Darwin-12.4.0-x86_64-i386-64bit
Ren'Py 6.15.7.374
Secure Self-Attachment Therapy 0.0
